<?xml version="1.0" encoding="utf-8"?>
<!-- This URDF was automatically created by SolidWorks to URDF Exporter! Originally created by Stephen Brawner (brawner@gmail.com) 
     Commit Version: 1.5.1-0-g916b5db  Build Version: 1.5.7152.31018
     For more information, please see http://wiki.ros.org/sw_urdf_exporter -->
<robot
  name="4wheel_behindnowheel">
  <link
    name="base_link">
    <inertial>
      <origin
        xyz="-0.015791268345538 0.000885138044595091 0.0685678092687935"
        rpy="0 0 0" />
      <mass
        value="5.32485366509135" />
      <inertia
        ixx="0.0149048926646328"
        ixy="-1.47975198124448E-06"
        ixz="-8.06521337681199E-06"
        iyy="0.0219378727233068"
        iyz="-4.01751561827566E-06"
        izz="0.0232029020939231" />
    </inertial>
    <visual>
      <origin
        xyz="0 0 0"
        rpy="0 0 0" />
      <geometry>
        <mesh
          filename="package://4wheel_behindnowheel/meshes/base_link.STL" />
      </geometry>
      <material
        name="">
        <color
          rgba="0.752941176470588 0.752941176470588 0.752941176470588 1" />
      </material>
    </visual>
    <collision>
      <origin
        xyz="0 0 0"
        rpy="0 0 0" />
      <geometry>
        <mesh
          filename="package://4wheel_behindnowheel/meshes/base_link.STL" />
      </geometry>
    </collision>
  </link>
  <link
    name="right_front_suspension">
    <inertial>
      <origin
        xyz="0.072447 -0.031683 0.02534"
        rpy="0 0 0" />
      <mass
        value="0.26437" />
      <inertia
        ixx="3.2075E-05"
        ixy="1.4412E-07"
        ixz="6.3085E-08"
        iyy="6.227E-05"
        iyz="-2.0189E-07"
        izz="6.2852E-05" />
    </inertial>
    <visual>
      <origin
        xyz="0 0 0"
        rpy="0 0 0" />
      <geometry>
        <mesh
          filename="package://4wheel_behindnowheel/meshes/right_front_suspension.STL" />
      </geometry>
      <material
        name="">
        <color
          rgba="0.75294 0.75294 0.75294 1" />
      </material>
    </visual>
    <collision>
      <origin
        xyz="0 0 0"
        rpy="0 0 0" />
      <geometry>
        <mesh
          filename="package://4wheel_behindnowheel/meshes/right_front_suspension.STL" />
      </geometry>
    </collision>
  </link>
  <joint
    name="right_front_suspension"
    type="prismatic">
    <origin
      xyz="0.11437 -0.21292 0.036427"
      rpy="2.834 0 1.5708" />
    <parent
      link="base_link" />
    <child
      link="right_front_suspension" />
    <axis
      xyz="0 0.3028 -0.95305" />
    <limit
      lower="0"
      upper="0"
      effort="0"
      velocity="0" />
  </joint>
  <link
    name="right_front_wheel">
    <inertial>
      <origin
        xyz="0.014171 0 -2.7756E-17"
        rpy="0 0 0" />
      <mass
        value="0.23877" />
      <inertia
        ixx="0.00029907"
        ixy="2.5831E-24"
        ixz="-8.1395E-23"
        iyy="0.00016737"
        iyz="-2.5411E-21"
        izz="0.00016737" />
    </inertial>
    <visual>
      <origin
        xyz="0 0 0"
        rpy="0 0 0" />
      <geometry>
        <mesh
          filename="package://4wheel_behindnowheel/meshes/right_front_wheel.STL" />
      </geometry>
      <material
        name="">
        <color
          rgba="1 1 1 1" />
      </material>
    </visual>
    <collision>
      <origin
        xyz="0 0 0"
        rpy="0 0 0" />
      <geometry>
        <mesh
          filename="package://4wheel_behindnowheel/meshes/right_front_wheel.STL" />
      </geometry>
    </collision>
  </link>
  <joint
    name="right_front_wheel"
    type="continuous">
    <origin
      xyz="0 -0.028286 0.058405"
      rpy="-1.1911 0 0" />
    <parent
      link="right_front_suspension" />
    <child
      link="right_front_wheel" />
    <axis
      xyz="1 0 0" />
    <limit
      effort="3.1"
      velocity="7" />
  </joint>
  <link
    name="left_front_suspension">
    <inertial>
      <origin
        xyz="0.066688 -0.025617 0.027258"
        rpy="0 0 0" />
      <mass
        value="0.26437" />
      <inertia
        ixx="3.2075E-05"
        ixy="-1.4412E-07"
        ixz="-6.3085E-08"
        iyy="6.227E-05"
        iyz="-2.0189E-07"
        izz="6.2852E-05" />
    </inertial>
    <visual>
      <origin
        xyz="0 0 0"
        rpy="0 0 0" />
      <geometry>
        <mesh
          filename="package://4wheel_behindnowheel/meshes/left_front_suspension.STL" />
      </geometry>
      <material
        name="">
        <color
          rgba="0.75294 0.75294 0.75294 1" />
      </material>
    </visual>
    <collision>
      <origin
        xyz="0 0 0"
        rpy="0 0 0" />
      <geometry>
        <mesh
          filename="package://4wheel_behindnowheel/meshes/left_front_suspension.STL" />
      </geometry>
    </collision>
  </link>
  <joint
    name="left_front_suspension"
    type="prismatic">
    <origin
      xyz="0.075688 0.20716 0.036427"
      rpy="2.834 0 -1.5708" />
    <parent
      link="base_link" />
    <child
      link="left_front_suspension" />
    <axis
      xyz="0 0.3028 -0.95305" />
    <limit
      lower="0"
      upper="0"
      effort="0"
      velocity="0" />
  </joint>
  <link
    name="left_front_wheel">
    <inertial>
      <origin
        xyz="-0.008411 0 0"
        rpy="0 0 0" />
      <mass
        value="0.23877" />
      <inertia
        ixx="0.00029907"
        ixy="4.2358E-22"
        ixz="8.4804E-23"
        iyy="0.00016737"
        iyz="6.7763E-21"
        izz="0.00016737" />
    </inertial>
    <visual>
      <origin
        xyz="0 0 0"
        rpy="0 0 0" />
      <geometry>
        <mesh
          filename="package://4wheel_behindnowheel/meshes/left_front_wheel.STL" />
      </geometry>
      <material
        name="">
        <color
          rgba="1 1 1 1" />
      </material>
    </visual>
    <collision>
      <origin
        xyz="0 0 0"
        rpy="0 0 0" />
      <geometry>
        <mesh
          filename="package://4wheel_behindnowheel/meshes/left_front_wheel.STL" />
      </geometry>
    </collision>
  </link>
  <joint
    name="left_front_wheel"
    type="continuous">
    <origin
      xyz="0 -0.047479 0.052309"
      rpy="-2.076 0 3.1416" />
    <parent
      link="left_front_suspension" />
    <child
      link="left_front_wheel" />
    <axis
      xyz="1 0 0" />
    <limit
      effort="3.1"
      velocity="7" />
  </joint>
  <link
    name="right_back_suspension">
    <inertial>
      <origin
        xyz="0.075402 -0.0095357 -0.022201"
        rpy="0 0 0" />
      <mass
        value="0.19701" />
      <inertia
        ixx="1.688E-05"
        ixy="3.707E-21"
        ixz="-6.4068E-22"
        iyy="5.0218E-05"
        iyz="1.0509E-06"
        izz="4.7245E-05" />
    </inertial>
    <visual>
      <origin
        xyz="0 0 0"
        rpy="0 0 0" />
      <geometry>
        <mesh
          filename="package://4wheel_behindnowheel/meshes/right_back_suspension.STL" />
      </geometry>
      <material
        name="">
        <color
          rgba="0.75294 0.75294 0.75294 1" />
      </material>
    </visual>
    <collision>
      <origin
        xyz="0 0 0"
        rpy="0 0 0" />
      <geometry>
        <mesh
          filename="package://4wheel_behindnowheel/meshes/right_back_suspension.STL" />
      </geometry>
    </collision>
  </link>
  <joint
    name="right_back_suspension"
    type="prismatic">
    <origin
      xyz="-0.07269 -0.20716 -0.0087739"
      rpy="2.834 0 1.5708" />
    <parent
      link="base_link" />
    <child
      link="right_back_suspension" />
    <axis
      xyz="0 0.3028 -0.95305" />
    <limit
      lower="0"
      upper="0"
      effort="0"
      velocity="0" />
  </joint>
  <link
    name="right_back_caster">
    <inertial>
      <origin
        xyz="4.0063E-07 -0.0037032 0"
        rpy="0 0 0" />
      <mass
        value="0.020987" />
      <inertia
        ixx="7.3202E-06"
        ixy="2.1294E-10"
        ixz="4.3949E-23"
        iyy="3.6659E-06"
        iyz="-4.815E-22"
        izz="8.246E-06" />
    </inertial>
    <visual>
      <origin
        xyz="0 0 0"
        rpy="0 0 0" />
      <geometry>
        <mesh
          filename="package://4wheel_behindnowheel/meshes/right_back_caster.STL" />
      </geometry>
      <material
        name="">
        <color
          rgba="0.79216 0.81961 0.93333 1" />
      </material>
    </visual>
    <collision>
      <origin
        xyz="0 0 0"
        rpy="0 0 0" />
      <geometry>
        <mesh
          filename="package://4wheel_behindnowheel/meshes/right_back_caster.STL" />
      </geometry>
    </collision>
  </link>
  <joint
    name="right_back_caster"
    type="continuous">
    <origin
      xyz="0.0411609911350767 -0.0150684419408277 -0.004787494193096"
      rpy="-1.2631660489123 0 0" />
    <parent
      link="right_back_suspension" />
    <child
      link="right_back_caster" />
    <axis
      xyz="0 1 0" />
  </joint>
  <link
    name="right_back_wheel">
    <inertial>
      <origin
        xyz="1.2669E-05 0 0"
        rpy="0 0 0" />
      <mass
        value="0.052036" />
      <inertia
        ixx="2.1966E-05"
        ixy="-1.3475E-38"
        ixz="-2.3698E-38"
        iyy="1.254E-05"
        iyz="3.3403E-40"
        izz="1.254E-05" />
    </inertial>
    <visual>
      <origin
        xyz="0 0 0"
        rpy="0 0 0" />
      <geometry>
        <mesh
          filename="package://4wheel_behindnowheel/meshes/right_back_wheel.STL" />
      </geometry>
      <material
        name="">
        <color
          rgba="1 1 1 1" />
      </material>
    </visual>
    <collision>
      <origin
        xyz="0 0 0"
        rpy="0 0 0" />
      <geometry>
        <mesh
          filename="package://4wheel_behindnowheel/meshes/right_back_wheel.STL" />
      </geometry>
    </collision>
  </link>
  <joint
    name="right_back_wheel"
    type="continuous">
    <origin
      xyz="0 -0.029028 0"
      rpy="0 0 0" />
    <parent
      link="right_back_caster" />
    <child
      link="right_back_wheel" />
    <axis
      xyz="1 0 0" />
  </joint>
  <link
    name="left_back_suspension">
    <inertial>
      <origin
        xyz="0.075402 -0.0095357 -0.022201"
        rpy="0 0 0" />
      <mass
        value="0.19701" />
      <inertia
        ixx="1.688E-05"
        ixy="1.1945E-20"
        ixz="1.0411E-20"
        iyy="5.0218E-05"
        iyz="1.0509E-06"
        izz="4.7245E-05" />
    </inertial>
    <visual>
      <origin
        xyz="0 0 0"
        rpy="0 0 0" />
      <geometry>
        <mesh
          filename="package://4wheel_behindnowheel/meshes/left_back_suspension.STL" />
      </geometry>
      <material
        name="">
        <color
          rgba="0.75294 0.75294 0.75294 1" />
      </material>
    </visual>
    <collision>
      <origin
        xyz="0 0 0"
        rpy="0 0 0" />
      <geometry>
        <mesh
          filename="package://4wheel_behindnowheel/meshes/left_back_suspension.STL" />
      </geometry>
    </collision>
  </link>
  <joint
    name="left_back_suspension"
    type="prismatic">
    <origin
      xyz="-0.10431 0.20716 -0.0087739"
      rpy="2.834 0 -1.5708" />
    <parent
      link="base_link" />
    <child
      link="left_back_suspension" />
    <axis
      xyz="0 0.3028 -0.95305" />
    <limit
      lower="0"
      upper="0"
      effort="0"
      velocity="0" />
  </joint>
  <link
    name="left_back_caster">
    <inertial>
      <origin
        xyz="3.6952E-07 -0.010637 0"
        rpy="0 0 0" />
      <mass
        value="0.022754" />
      <inertia
        ixx="9.8996E-06"
        ixy="2.3871E-10"
        ixz="-3.9352E-22"
        iyy="3.7156E-06"
        iyz="4.2404E-22"
        izz="1.0825E-05" />
    </inertial>
    <visual>
      <origin
        xyz="0 0 0"
        rpy="0 0 0" />
      <geometry>
        <mesh
          filename="package://4wheel_behindnowheel/meshes/left_back_caster.STL" />
      </geometry>
      <material
        name="">
        <color
          rgba="0.79216 0.81961 0.93333 1" />
      </material>
    </visual>
    <collision>
      <origin
        xyz="0 0 0"
        rpy="0 0 0" />
      <geometry>
        <mesh
          filename="package://4wheel_behindnowheel/meshes/left_back_caster.STL" />
      </geometry>
    </collision>
  </link>
  <joint
    name="left_back_caster"
    type="continuous">
    <origin
      xyz="0.0411609911350767 -0.0150684419408277 -0.00478749419309602"
      rpy="-1.87842660467749 0 3.14159265358979" />
    <parent
      link="left_back_suspension" />
    <child
      link="left_back_caster" />
    <axis
      xyz="0 1 0" />
  </joint>
  <link
    name="left_back_wheel">
    <inertial>
      <origin
        xyz="1.2669E-05 0 0"
        rpy="0 0 0" />
      <mass
        value="0.052036" />
      <inertia
        ixx="2.1966E-05"
        ixy="-1.3475E-38"
        ixz="-2.3698E-38"
        iyy="1.254E-05"
        iyz="3.3403E-40"
        izz="1.254E-05" />
    </inertial>
    <visual>
      <origin
        xyz="0 0 0"
        rpy="0 0 0" />
      <geometry>
        <mesh
          filename="package://4wheel_behindnowheel/meshes/left_back_wheel.STL" />
      </geometry>
      <material
        name="">
        <color
          rgba="1 1 1 1" />
      </material>
    </visual>
    <collision>
      <origin
        xyz="0 0 0"
        rpy="0 0 0" />
      <geometry>
        <mesh
          filename="package://4wheel_behindnowheel/meshes/left_back_wheel.STL" />
      </geometry>
    </collision>
  </link>
  <joint
    name="left_back_wheel"
    type="continuous">
    <origin
      xyz="0 -0.0390282868227122 0"
      rpy="0 0 0" />
    <parent
      link="left_back_caster" />
    <child
      link="left_back_wheel" />
    <axis
      xyz="1 0 0" />
  </joint>
  <link
    name="cam1">
    <inertial>
      <origin
        xyz="0.049836 0.061784 0.068723"
        rpy="0 0 0" />
      <mass
        value="0.043612" />
      <inertia
        ixx="4.2948E-06"
        ixy="-8.8548E-10"
        ixz="-1.0183E-09"
        iyy="2.2106E-05"
        iyz="2.1758E-08"
        izz="2.3571E-05" />
    </inertial>
    <visual>
      <origin
        xyz="0 0 0"
        rpy="0 0 0" />
      <geometry>
        <mesh
          filename="package://4wheel_behindnowheel/meshes/cam1.STL" />
      </geometry>
      <material
        name="">
        <color
          rgba="0.79216 0.81961 0.93333 1" />
      </material>
    </visual>
    <collision>
      <origin
        xyz="0 0 0"
        rpy="0 0 0" />
      <geometry>
        <mesh
          filename="package://4wheel_behindnowheel/meshes/cam1.STL" />
      </geometry>
    </collision>
  </link>
  <joint
    name="cam1"
    type="fixed">
    <origin
      xyz="0.022219 -0.049835 0.11022"
      rpy="2.3562 0 1.5708" />
    <parent
      link="base_link" />
    <child
      link="cam1" />
    <axis
      xyz="0 0 0" />
  </joint>
  <link
    name="cam2">
    <inertial>
      <origin
        xyz="0.051723 0.061784 0.068723"
        rpy="0 0 0" />
      <mass
        value="0.043612" />
      <inertia
        ixx="4.2948E-06"
        ixy="-8.8579E-10"
        ixz="-1.0181E-09"
        iyy="2.2106E-05"
        iyz="2.1758E-08"
        izz="2.3571E-05" />
    </inertial>
    <visual>
      <origin
        xyz="0 0 0"
        rpy="0 0 0" />
      <geometry>
        <mesh
          filename="package://4wheel_behindnowheel/meshes/cam2.STL" />
      </geometry>
      <material
        name="">
        <color
          rgba="0.79216 0.81961 0.93333 1" />
      </material>
    </visual>
    <collision>
      <origin
        xyz="0 0 0"
        rpy="0 0 0" />
      <geometry>
        <mesh
          filename="package://4wheel_behindnowheel/meshes/cam2.STL" />
      </geometry>
    </collision>
  </link>
  <joint
    name="cam2"
    type="prismatic">
    <origin
      xyz="0.046422 -0.048745 0.079504"
      rpy="1.5708 0 1.5708" />
    <parent
      link="base_link" />
    <child
      link="cam2" />
    <axis
      xyz="1 0 0" />
    <limit
      lower="0"
      upper="0"
      effort="0"
      velocity="0" />
  </joint>
  <link
    name="lidar">
    <inertial>
      <origin
        xyz="-0.077156 0.74443 -0.036403"
        rpy="0 0 0" />
      <mass
        value="0.073085" />
      <inertia
        ixx="1.9581E-05"
        ixy="-4.2839E-07"
        ixz="1.0393E-07"
        iyy="4.1418E-05"
        iyz="-9.4271E-09"
        izz="2.4125E-05" />
    </inertial>
    <visual>
      <origin
        xyz="0 0 0"
        rpy="0 0 0" />
      <geometry>
        <mesh
          filename="package://4wheel_behindnowheel/meshes/lidar.STL" />
      </geometry>
      <material
        name="">
        <color
          rgba="0.79216 0.81961 0.93333 1" />
      </material>
    </visual>
    <collision>
      <origin
        xyz="0 0 0"
        rpy="0 0 0" />
      <geometry>
        <mesh
          filename="package://4wheel_behindnowheel/meshes/lidar.STL" />
      </geometry>
    </collision>
  </link>
  <joint
    name="lidar"
    type="prismatic">
    <origin
      xyz="0.0019925 0.032539 -0.56169"
      rpy="1.5708 0 -3.1337" />
    <parent
      link="base_link" />
    <child
      link="lidar" />
    <axis
      xyz="0.0078706 0 -0.99997" />
    <limit
      lower="0"
      upper="0"
      effort="0"
      velocity="0" />
  </joint>
</robot>